Workbook

Sheet Scraper-Verified
A1: ID | B1: Address | C1: Latitude | D1: Longitude | E1: Phone Number | F1: Name of Service | G1: Restrictions of Service | H1: Days of Service | I1: Cateogry of Help | J1: Description | K1: link to site | L1: Reliability Description | M1: Reliability Score | N1: Confidence | O1: Confidence Details | P1: Date Verified | Q1: Classification
A2: 1 | B2: 1731 E Chase St, Baltimore, MD 21213 | C2: 39.303176 | D2: -76.592979 | E2: (410) 545-0136 | F2: The Community Resource Center | G2: Residents in catchment area | H2: Monday: 8:30 AM to 4:30 PM; Tuesday: 8:30 AM to 4:30 PM; Wednesday: 8:30 AM to 4:30 PM; Thursday: 8:30 AM to 4:30 PM; Friday: 8:30 AM to 4:30 PM; Saturday: Closed; Sunday: Closed | I2: Other / Uncategorized | J2: A physical community resource center located at the supplied Baltimore address. Publicly available sources do not provide clear, attributable details about specific programs, eligibility rules, or services offered at this location. | L2: Public review text is sparse: most Google reviewers left star ratings without comments, so substantive feedback is limited. The few written comments report crowding and at least one complaint about perceived staff impatience; several recent anonymous low-star ratings exist but provide no explanatory detail. Because review content is thin and the organization’s website could not be verified, qualitative impressions are provisional. | M2: 67.472471 | N2: 47.576945 | O2: accepted google identity: 14.2/15; review volume: 22.1/30; review consistency: 2.3/7; review freshness: 7.3/8; verified website: 0.0/15; confirmed irs record: 0.0/20; source corroboration: 1.7/5; Synthesis metadata: insufficient_evidence (not part of numeric confidence) | P2: 8312026 | Q2: =IF(OR(ISBLANK(M2), ISBLANK(N2)), "", IF(N2 < Sheet3!$B$6, "Insufficient Reviews", IF(M2 >= Sheet3!$B$2, "Highly Reliable", IF(M2 >= Sheet3!$B$3, "Reliable", IF(M2 >= Sheet3!$B$4, "Mixed Reviews", "Low Reliability"))))) -> Mixed Reviews
A3: =A2+1 -> 2 | B3: 5225 York Rd #4, Baltimore, MD 21212 | C3: 39.35388 | D3: -76.609677 | E3: (410) 396-6084 | F3: Northern Community Action | G3: Residents in catchment area | H3: Monday: 8:30 AM to 3:30 PM; Tuesday: 8:30 AM to 3:30 PM; Wednesday: 8:30 AM to 3:30 PM; Thursday: 8:30 AM to 3:30 PM; Friday: 8:30 AM to 3:30 PM; Saturday: Closed; Sunday: Closed | I3: Youth, Family, & General Support Services | J3: A neighborhood community center / social services office that provides in-person assistance and referrals to other agencies for residents seeking help with social supports and benefit programs. | L3: Review text shows a mix of experiences: many reviewers describe staff as helpful and able to provide resources or get things done, while a recurring negative theme is long wait times and occasional reports of rude or unprofessional staff. The most recent reviews continue to show this mixed pattern, with some recent 5-star praise alongside isolated low-star reports about service and wait time. Attempts to corroborate program details on an official website were unsuccessful, which limits confirmation of specific services beyond what reviewers report and the Google listing. | M3: 67.055632 | N3: 54.105562 | O3: accepted google identity: 14.2/15; review volume: 30.0/30; review consistency: 1.0/7; review freshness: 7.2/8; verified website: 0.0/15; confirmed irs record: 0.0/20; source corroboration: 1.7/5; Synthesis metadata: medium (not part of numeric confidence) | P3: 8312026 | Q3: =IF(OR(ISBLANK(M3), ISBLANK(N3)), "", IF(N3 < Sheet3!$B$6, "Insufficient Reviews", IF(M3 >= Sheet3!$B$2, "Highly Reliable", IF(M3 >= Sheet3!$B$3, "Reliable", IF(M3 >= Sheet3!$B$4, "Mixed Reviews", "Low Reliability"))))) -> Mixed Reviews
A4: =A3+1 -> 3 | B4: Tower II, 100 S Charles St 8th floor, Baltimore, MD 21201 | C4: 39.286971 | D4: -76.615731 | E4: (410) 637-1900 | F4: Behavioral Health System Baltimore | G4: 988 crisis support is available by call or text and is described as free and confidential for residents in Baltimore City, Baltimore County, Howard County, and Carroll County. Bmore POWER provides citywide harm-reduction outreach and posts an outreach schedule; materials and services referenced include naloxone and drug-testing resources. No additional intake documents, referral-only restrictions, or eligibility requirements were stated in the available sources. | H4: Monday: 8 AM to 5 PM; Tuesday: 8 AM to 5 PM; Wednesday: 8 AM to 5 PM; Thursday: 8 AM to 5 PM; Friday: 8 AM to 5 PM; Saturday: Closed; Sunday: Closed | I4: Behavioral Health, Substance Use, & Crisis | J4: A city-level behavioral health coordinating organization that operates a 988 crisis helpline for the region, runs a harm-reduction outreach team (Bmore POWER) offering on-the-ground outreach and overdose-harm-reduction services, and manages complaints and system navigation for behavioral-health providers in Baltimore City. | K4: http://www.bhsbaltimore.org/ | L4: Public review feedback is very limited; the available recent review expresses that the reviewer felt their concerns were ignored and reports distrust of health-care professionals, and the listing owner did not post a response. The organization’s official website and archival snapshots corroborate described programs (988 helpline, Bmore POWER outreach, complaint management), supporting the identity and stated activities. Because review text is sparse and skewed negative, user-experience claims should be treated cautiously and are not broadly generalizable. | M4: 46.873173 | N4: 71.549732 | O4: accepted google identity: 14.2/15; review volume: 8.9/30; review consistency: 7.0/7; review freshness: 2.2/8; verified website: 14.2/15; confirmed irs record: 20.0/20; source corroboration: 5.0/5; Synthesis metadata: high (not part of numeric confidence) | P4: 8312026 | Q4: =IF(OR(ISBLANK(M4), ISBLANK(N4)), "", IF(N4 < Sheet3!$B$6, "Insufficient Reviews", IF(M4 >= Sheet3!$B$2, "Highly Reliable", IF(M4 >= Sheet3!$B$3, "Reliable", IF(M4 >= Sheet3!$B$4, "Mixed Reviews", "Low Reliability"))))) -> Low Reliability
A5: =A4+1 -> 4 | B5: 4200 Pennington Ave, Baltimore, MD 21226 | C5: 39.227395 | D5: -76.58888 | E5: (443) 300-1177 | F5: Unlimited Bounds Human Services | G5: Contact an admissions coordinator to begin services (phone and contact form available); the website states an admissions coordinator will respond within two business days. Prospective clients are asked to contact admissions to confirm insurance acceptance and intake details; the site describes an intake team that facilitates initiation of services. | H5: Monday: 9 AM to 5 PM; Tuesday: 9 AM to 5 PM; Wednesday: 9 AM to 5 PM; Thursday: 9 AM to 5 PM; Friday: 9 AM to 5 PM; Saturday: 9 AM to 5 PM; Sunday: 9 AM to 5 PM | I5: Behavioral Health, Substance Use, & Crisis | J5: A Baltimore-based behavioral health provider offering multi-level addiction treatment and associated mental health care, including structured day programs, outpatient treatment, individual and group therapy, medication management, residential/housing support, and telehealth options. | K5: https://unlimitedbounds.com/ | L5: Google Maps reviews show a substantial set of first-hand client feedback: many reviewers praise caring, committed staff and describe effective PHP/IOP programming, on-site housing, and meals; recurring criticisms include staff turnover, small food portions, and delays or problems getting psychiatric medications. The organization’s verified website and Google Maps listing consistently describe a multi-level addiction-treatment continuum (PHP, IOP, outpatient), residential/housing services, medication management/psychiatry, and telehealth, which aligns with reviewer accounts. Newer reviews continue to show a mix of strong endorsements and sharp operational complaints, so public feedback is mixed but consistent with the services advertised. | M5: 71.935244 | N5: 69.45683 | O5: accepted google identity: 13.5/15; review volume: 30.0/30; review consistency: 1.4/7; review freshness: 7.7/8; verified website: 13.5/15; confirmed irs record: 0.0/20; source corroboration: 3.3/5; Synthesis metadata: high (not part of numeric confidence) | P5: 8312026 | Q5: =IF(OR(ISBLANK(M5), ISBLANK(N5)), "", IF(N5 < Sheet3!$B$6, "Insufficient Reviews", IF(M5 >= Sheet3!$B$2, "Highly Reliable", IF(M5 >= Sheet3!$B$3, "Reliable", IF(M5 >= Sheet3!$B$4, "Mixed Reviews", "Low Reliability"))))) -> Reliable
A6: =A5+1 -> 5 | B6: 4201 Primrose Ave, Baltimore, MD 21215 | C6: 39.349402 | D6: -76.695859 | E6: (410) 764-8560 | F6: People Encouraging People | G6: Enrollment in PEP services is implied for ongoing support; the website instructs enrolled clients to call their usual PEP office and notes an after-hours on-call number will connect when needed. (Evidence: official website and Google Maps listing.) | H6: Monday: 8:30 AM to 5 PM; Tuesday: 8:30 AM to 5 PM; Wednesday: 8:30 AM to 5 PM; Thursday: 8:30 AM to 5 PM; Friday: 8:30 AM to 5 PM; Saturday: Closed; Sunday: Closed | I6: Behavioral Health, Substance Use, & Crisis | J6: PEP (People Encouraging People) operates a physical recovery/behavioral health program that provides community-based rehabilitation and individualized support services for people with psychiatric or other disabling conditions; the organization’s website also states it is accredited by The Joint Commission. | K6: http://www.peponline.org/ | L6: Recent reviewer comments are mixed: many people report helpful, caring, communicative staff who supported intake, housing assistance, or other services, while other reviewers describe serious safety and housing-related problems at some PEP sites, including allegations of unaddressed violence and pest issues. The most recent reviews include both brief positive reports and one detailed, severe complaint about a past site, so public feedback is currently mixed rather than uniformly positive or uniformly negative. | M6: 69.190493 | N6: 70.645529 | O6: accepted google identity: 14.2/15; review volume: 30.0/30; review consistency: 3.0/7; review freshness: 5.8/8; verified website: 14.2/15; confirmed irs record: 0.0/20; source corroboration: 3.3/5; Synthesis metadata: medium (not part of numeric confidence) | P6: 8312026 | Q6: =IF(OR(ISBLANK(M6), ISBLANK(N6)), "", IF(N6 < Sheet3!$B$6, "Insufficient Reviews", IF(M6 >= Sheet3!$B$2, "Highly Reliable", IF(M6 >= Sheet3!$B$3, "Reliable", IF(M6 >= Sheet3!$B$4, "Mixed Reviews", "Low Reliability"))))) -> Mixed Reviews
A7: =A6+1 -> 6 | B7: 25 S Charles St, Baltimore, MD 21201 | C7: 39.288203 | D7: -76.61451 | E7: (800) 332-6347 | F7: Maryland Department of Human Services | G7: Contact DHS for services and intake by phone (1-800-332-6347) with TTY 1-800-735-2258; report adult or child abuse via the dedicated hotline (1-800-917-7383). SNAP and energy-assistance programs require application/eligibility processes (energy-assistance program year runs 7/1–6/30). Child Protective Services uses investigative or alternative responses depending on assessed risk. (Access details as stated on DHS website and the Google Maps listing.) | H7: Monday: 8:30 AM to 5 PM; Tuesday: 8:30 AM to 5 PM; Wednesday: 8:30 AM to 5 PM; Thursday: 8:30 AM to 5 PM; Friday: 8:30 AM to 5 PM; Saturday: Closed; Sunday: Closed | I7: Food & Essential Needs | J7: Maryland Department of Human Services operates statewide social-service programs including adult services (support for elderly and adults with disabilities), child protective services, administration of food benefits (SNAP), and energy/utility assistance programs. | K7: http://dhs.maryland.gov/ | L7: Google reviewers most frequently report long phone wait times, lost paperwork, communication breakdowns, and negative experiences with staff responsiveness—some reviewers describe serious problems with adult protective services responses. Recurring positive comments note that individual staff or front-desk workers can be helpful and patient when reached. The newest reviews continue to emphasize frustration and perceived systemic inefficiency, while positive experiences remain present but less common. | M7: 46.883036 | N7: 70.64272 | O7: accepted google identity: 14.2/15; review volume: 30.0/30; review consistency: 1.0/7; review freshness: 7.8/8; verified website: 14.2/15; confirmed irs record: 0.0/20; source corroboration: 3.3/5; Synthesis metadata: high (not part of numeric confidence) | P7: 8312026 | Q7: =IF(OR(ISBLANK(M7), ISBLANK(N7)), "", IF(N7 < Sheet3!$B$6, "Insufficient Reviews", IF(M7 >= Sheet3!$B$2, "Highly Reliable", IF(M7 >= Sheet3!$B$3, "Reliable", IF(M7 >= Sheet3!$B$4, "Mixed Reviews", "Low Reliability"))))) -> Low Reliability
A8: =A7+1 -> 7 | B8: 3549 Old Frederick Rd, Baltimore, MD 21229 | C8: 39.28273 | D8: -76.676759 | E8: (410) 837-1400 | F8: Project Plase | G8: Intake requires completing an intake application; SSVF and some veteran programs are for qualified veterans and may prioritize chronically homeless veterans. Some programs require case management intake and referrals. Site accessibility features reported (wheelchair accessible entrance and parking). | H8: Monday: 9 AM to 3 PM; Tuesday: 9 AM to 3 PM; Wednesday: 9 AM to 3 PM; Thursday: 9 AM to 3 PM; Friday: 9 AM to 3 PM; Saturday: Closed; Sunday: Closed | I8: Housing & Shelter | J8: Project PLASE provides temporary emergency housing and longer-term supportive and subsidized housing programs, plus case management and wraparound supportive services (including a veteran-focused SSVF program) to help people move from homelessness into stable housing. | K8: https://projectplase.org/ | L8: Google reviewers commonly report that staff are helpful and that the program has assisted people in obtaining safe, stable housing; several reviews specifically praise staff and the program’s housing outcomes. Recurring negative feedback centers on at least one user being told help was unavailable after arrival, indicating occasional access or capacity problems. The recent reviews in the sample remain largely positive, and organizational identity is corroborated by an IRS registry match and an official website. | M8: 82.134922 | N8: 92.168783 | O8: accepted google identity: 13.5/15; review volume: 30.0/30; review consistency: 3.1/7; review freshness: 7.1/8; verified website: 13.5/15; confirmed irs record: 20.0/20; source corroboration: 5.0/5; Synthesis metadata: high (not part of numeric confidence) | P8: 8312026 | Q8: =IF(OR(ISBLANK(M8), ISBLANK(N8)), "", IF(N8 < Sheet3!$B$6, "Insufficient Reviews", IF(M8 >= Sheet3!$B$2, "Highly Reliable", IF(M8 >= Sheet3!$B$3, "Reliable", IF(M8 >= Sheet3!$B$4, "Mixed Reviews", "Low Reliability"))))) -> Highly Reliable
A9: =A8+1 -> 8 | B9: 4120 Patterson Ave, Baltimore, MD 21215 | C9: 39.355171 | D9: -76.704672 | E9: (410) 764-2266 | F9: Park West Health System | G9: Appointments are recommended and/or required. The center states it provides care regardless of ability to pay and offers free or low-cost care based on individual circumstances. (Evidence supports appointment-based intake and sliding-scale/low-cost options.) | H9: Monday: 9 AM to 5:30 PM; Tuesday: 9 AM to 5:30 PM; Wednesday: 9 AM to 5:30 PM; Thursday: 9 AM to 5:30 PM; Friday: 9 AM to 5:30 PM; Saturday: Closed; Sunday: Closed | I9: Physical & General Health Care | J9: A community-based medical clinic and federally qualified health center that provides primary and preventive medical care, pediatrics, behavioral health, and related services across multiple Park West locations in Northwest Baltimore. | K9: http://www.parkwestmed.org/ | L9: Google Maps reviewers repeatedly praise individual clinicians and some staff for good patient interactions and attentive providers. Recurring negative themes include difficulty scheduling or getting timely appointment responses, long waits and missed provider visits, billing or insurance handling problems, and concerns about medication management or care continuity. The newest reviews in the fetched sample emphasize those access and scheduling problems rather than contradicting them. | M9: 69.081243 | N9: 70.645769 | O9: accepted google identity: 14.2/15; review volume: 30.0/30; review consistency: 1.0/7; review freshness: 7.8/8; verified website: 14.2/15; confirmed irs record: 0.0/20; source corroboration: 3.3/5; Synthesis metadata: high (not part of numeric confidence) | P9: 8312026 | Q9: =IF(OR(ISBLANK(M9), ISBLANK(N9)), "", IF(N9 < Sheet3!$B$6, "Insufficient Reviews", IF(M9 >= Sheet3!$B$2, "Highly Reliable", IF(M9 >= Sheet3!$B$3, "Reliable", IF(M9 >= Sheet3!$B$4, "Mixed Reviews", "Low Reliability"))))) -> Mixed Reviews
A10: =A9+1 -> 9 | B10: 1501 W Saratoga St, Baltimore, MD 21223 | C10: 39.291894 | D10: -76.641619 | E10: (410) 383-8300 | F10: Total Health Care - Saratoga Health Center | G10: Open to all; accepts most insurance | H10: Monday: 8:30 AM to 7 PM; Tuesday: 8:30 AM to 7 PM; Wednesday: 8:30 AM to 7 PM; Thursday: 8:30 AM to 7 PM; Friday: 8:30 AM to 6 PM; Saturday: Closed; Sunday: Closed | I10: Physical & General Health Care | J10: A medical clinic / community health center providing general primary and outpatient medical care. The facility’s listing indicates on-site pharmacy services and behavioral health/counseling services. | K10: http://www.totalhealthcare.org/ | L10: Reviewers commonly praise the clinic’s staff and find the location convenient, reporting positive experiences with providers. Recurring complaints describe administrative problems — such as appointment redirections, delays or problems with deliveries and dental follow‑through, and occasional unexpected closures — which have led to some negative experiences. The owner has replied to some reviews; the most recent feedback includes positive reports but the mix of criticisms suggests service consistency can vary. | M10: 73.322945 | N10: 71.404651 | O10: accepted google identity: 14.2/15; review volume: 30.0/30; review consistency: 1.6/7; review freshness: 8.0/8; verified website: 14.2/15; confirmed irs record: 0.0/20; source corroboration: 3.3/5; Synthesis metadata: medium (not part of numeric confidence) | P10: 8312026 | Q10: =IF(OR(ISBLANK(M10), ISBLANK(N10)), "", IF(N10 < Sheet3!$B$6, "Insufficient Reviews", IF(M10 >= Sheet3!$B$2, "Highly Reliable", IF(M10 >= Sheet3!$B$3, "Reliable", IF(M10 >= Sheet3!$B$4, "Mixed Reviews", "Low Reliability"))))) -> Reliable
A11: =A10+1 -> 10 | B11: 5807 Harford Rd, Baltimore, MD 21214 | C11: 39.355368 | D11: -76.558075 | E11: (410) 444-2100 | F11: Harbel Community Organization | G11: Offers services to residents of Baltimore City and Baltimore County; homebuyers are advised to seek services from the housing counseling agency serving the area where they are most likely to purchase a home. Serves both adults and adolescents. (Access details and intake documentation requirements were not specified in the supplied evidence.) | H11: Monday: 9 AM to 7 PM; Tuesday: 9 AM to 7 PM; Wednesday: 9 AM to 7 PM; Thursday: 9 AM to 7 PM; Friday: 9 AM to 2 PM; Saturday: Closed; Sunday: Closed | I11: Housing & Shelter | J11: A neighborhood community organization that provides housing-related programs (housing counseling and homebuyer education/workshops), prevention and recovery services for substance use and mental health, and broader community relation/service activities serving the Northeast Baltimore area. | K11: http://www.harbel.org/ | L11: Google Maps reviewers most frequently praise educational homebuyer workshops and describe staff as helpful, professional, and patient; recent reviews are strongly positive and describe free, informative workshops. A minority of older reviews raise concerns about staff interactions and participant requirements for classes. Administrative records and the organization website corroborate the listed programs and identity. | M11: 78.837342 | N11: 92.494337 | O11: accepted google identity: 14.2/15; review volume: 30.0/30; review consistency: 1.4/7; review freshness: 7.6/8; verified website: 14.2/15; confirmed irs record: 20.0/20; source corroboration: 5.0/5; Synthesis metadata: high (not part of numeric confidence) | P11: 8312026 | Q11: =IF(OR(ISBLANK(M11), ISBLANK(N11)), "", IF(N11 < Sheet3!$B$6, "Insufficient Reviews", IF(M11 >= Sheet3!$B$2, "Highly Reliable", IF(M11 >= Sheet3!$B$3, "Reliable", IF(M11 >= Sheet3!$B$4, "Mixed Reviews", "Low Reliability"))))) -> Reliable
A12: =A11+1 -> 11 | B12: 3009 Greenmount Ave, Baltimore, MD 21218 | C12: 39.324853 | D12: -76.608877 | E12: (410) 547-9934 | F12: The Forge of The BIT Center | G12: Some programs (for example, cooking classes) require advance registration; sign-up information and program details are published on the organization's website. | H12: Monday: Closed; Tuesday: 10 AM to 5 PM; Wednesday: 10 AM to 5 PM; Thursday: 10 AM to 5 PM; Friday: 10 AM to 5 PM; Saturday: Closed; Sunday: Closed | I12: Food & Essential Needs | J12: A neighborhood community center providing food access and gastronomy education alongside cultural arts, youth empowerment, and workforce-development programs. | K12: http://www.thebitcenter.org/ | L12: Available reviewer feedback praises accommodating staff and homemade food offerings and specifically mentions community food provision and pasta made from scratch. The single provided review contains only positive remarks and does not raise operational concerns. The organization's official website and a confirmed registry record further corroborate the programs and contact details listed on the public map entry. | M12: 89.357004 | N12: 73.100765 | O12: accepted google identity: 14.2/15; review volume: 5.0/30; review consistency: 7.0/7; review freshness: 7.6/8; verified website: 14.2/15; confirmed irs record: 20.0/20; source corroboration: 5.0/5; Synthesis metadata: high (not part of numeric confidence) | P12: 8312026 | Q12: =IF(OR(ISBLANK(M12), ISBLANK(N12)), "", IF(N12 < Sheet3!$B$6, "Insufficient Reviews", IF(M12 >= Sheet3!$B$2, "Highly Reliable", IF(M12 >= Sheet3!$B$3, "Reliable", IF(M12 >= Sheet3!$B$4, "Mixed Reviews", "Low Reliability"))))) -> Highly Reliable
A13: =A12+1 -> 12 | B13: 3600 Clipper Mill Rd Ste 212, Baltimore, MD 21211 | C13: 39.330921 | D13: -76.642304 | E13: (443) 726-1318 | F13: LifeSpring Counseling | G13: Appointments are required/recommended; online scheduling available 24/7 and a dedicated staff member answers phones Monday–Friday during posted hours. The practice accepts insurance and advertises quick appointment availability (appointments often within about a week). Psychedelic‑assisted therapy (KAP) requires a preliminary consultation (free 15‑minute consult offered, contact by email per website). Services are offered both in‑person at the Baltimore office and via telehealth statewide in Maryland. | H13: Monday: 9 AM to 5 PM; Tuesday: 9 AM to 5 PM; Wednesday: 9 AM to 5 PM; Thursday: 9 AM to 5 PM; Friday: 9 AM to 5 PM; Saturday: Closed; Sunday: Closed | I13: Behavioral Health, Substance Use, & Crisis | J13: A Maryland counseling practice offering in-person and telehealth therapy, providing individual counseling for anxiety, depression, trauma/PTSD, and related concerns; the practice advertises specialized modalities including Brainspotting and psychedelic‑assisted therapy (KAP), and indicates it accepts insurance and schedules appointments quickly. | K13: http://lifespringcounseling.net/ | L13: Public reviewer comments emphasize compassionate, nurturing, and supportive clinicians; the most recent review echoes those positive themes. However, written review text is sparse and dated, so user-feedback evidence is limited and should be generalized cautiously. Non‑review corroborating sources (the Google business listing and the practice website) consistently show reachable website, posted hours, in‑person and telehealth service options, appointment requirements, and insurance acceptance. | M13: 67.437856 | N13: 51.939161 | O13: accepted google identity: 14.2/15; review volume: 12.0/30; review consistency: 7.0/7; review freshness: 1.2/8; verified website: 14.2/15; confirmed irs record: 0.0/20; source corroboration: 3.3/5; Synthesis metadata: high (not part of numeric confidence) | P13: 8312026 | Q13: =IF(OR(ISBLANK(M13), ISBLANK(N13)), "", IF(N13 < Sheet3!$B$6, "Insufficient Reviews", IF(M13 >= Sheet3!$B$2, "Highly Reliable", IF(M13 >= Sheet3!$B$3, "Reliable", IF(M13 >= Sheet3!$B$4, "Mixed Reviews", "Low Reliability"))))) -> Mixed Reviews
A14: =A13+1 -> 13 | B14: 5124 Greenwich Ave, Baltimore, MD 21229 | C14: 39.290394 | D14: -76.709523 | E14: (410) 433-5255 | F14: CarePoint Response | G14: Provides 24/7 access to crisis support (including via the 988 helpline). Residential and outpatient services accept Medicare, Medicaid, uninsured clients, and veterans. Provider referrals: be prepared to provide a face sheet and all clinical documentation (notes, reports, test results, exams). The site indicates referrals are accepted and that the organization follows up on referrals (website says follow-up within 24 hours). | H14: Monday: Open 24 hours; Tuesday: Open 24 hours; Wednesday: Open 24 hours; Thursday: Open 24 hours; Friday: Open 24 hours; Saturday: Open 24 hours; Sunday: Open 24 hours | I14: Behavioral Health, Substance Use, & Crisis | J14: A 24/7 crisis-response organization providing trauma-informed behavioral health and substance-use crisis services, including a 988 helpline backup, on-demand mobile response teams, short-term residential stabilization and a substance-use urgent care option, plus case management, care coordination, diversion programs, and training/outreach for partners. | K14: https://carepointresponse.org/ | L14: Public feedback is mixed. Several recent reviewers left high ratings without written comments, while multiple low-rated reviews include detailed complaints about residential conditions and frustration with housing voucher processes and case-management continuity. The organization’s website and its Google Business profile consistently describe 24/7 crisis services, residential and substance-use stabilization, mobile response, and case management, which corroborates the service types; however, reviewer text raises recurring concerns about facility upkeep and administrative delays. | M14: 65.560475 | N14: 56.801408 | O14: accepted google identity: 14.2/15; review volume: 18.0/30; review consistency: 0.0/7; review freshness: 7.0/8; verified website: 14.2/15; confirmed irs record: 0.0/20; source corroboration: 3.3/5; Synthesis metadata: high (not part of numeric confidence) | P14: 8312026 | Q14: =IF(OR(ISBLANK(M14), ISBLANK(N14)), "", IF(N14 < Sheet3!$B$6, "Insufficient Reviews", IF(M14 >= Sheet3!$B$2, "Highly Reliable", IF(M14 >= Sheet3!$B$3, "Reliable", IF(M14 >= Sheet3!$B$4, "Mixed Reviews", "Low Reliability"))))) -> Mixed Reviews
A15: =A14+1 -> 14 | B15: 400 S Bond St, Baltimore, MD 21231 | C15: 39.286352 | D15: -76.595716 | E15: (410) 732-1892 | F15: Beans & Bread | G15: Wheelchair accessible entrance and wheelchair accessible parking lot (Google Maps). Located within St Vincent De Paul (Google Maps). No verified, sitewide eligibility, intake, or documentation requirements were found in the available evidence. | H15: Monday: 9 AM to 2 PM; Tuesday: 9 AM to 2 PM; Wednesday: 9 AM to 2 PM; Thursday: 9 AM to 2 PM; Friday: 9 AM to 2 PM; Saturday: Closed; Sunday: Closed | I15: Food & Essential Needs | J15: A street‑level service site that provides on-site meals and food distribution and offers basic hygiene and support services (reviewers report showers, free laundry, and help establishing a mailing address). | K15: http://www.vincentbaltimore.org/get-help | L15: Google Maps reviewers commonly praise the quality of meals and the compassion of staff, and multiple recent reviewers specifically mention daily hot meals and available laundry and shower facilities. Recurring concerns in the reviews include complaints about cleanliness, restrictive on-site rules, and some reports of not receiving housing help or experiencing perceived discrimination. The newest reviews still highlight positive experiences around food and mailing/address assistance, so recent feedback continues the overall mixed-but-often-positive pattern. | M15: 74.210889 | N15: 70.344697 | O15: accepted google identity: 13.5/15; review volume: 30.0/30; review consistency: 2.1/7; review freshness: 7.9/8; verified website: 13.5/15; confirmed irs record: 0.0/20; source corroboration: 3.3/5; Synthesis metadata: high (not part of numeric confidence) | P15: 8312026 | Q15: =IF(OR(ISBLANK(M15), ISBLANK(N15)), "", IF(N15 < Sheet3!$B$6, "Insufficient Reviews", IF(M15 >= Sheet3!$B$2, "Highly Reliable", IF(M15 >= Sheet3!$B$3, "Reliable", IF(M15 >= Sheet3!$B$4, "Mixed Reviews", "Low Reliability"))))) -> Reliable
... A18: =A17+1 -> 17 | B18: 400 Cathedral St, Baltimore, MD 21201 | C18: 39.294555 | D18: -76.617217 | E18: (410) 396-5430 | F18: Enoch Pratt Free Library - Central Library | G18: Books by Mail: available to Baltimore City residents of all ages who are unable to visit the library due to a permanent or temporary disability. Book a Librarian: free 60-minute appointment available in-person, by phone, or via video (requires booking). Telephone reference is available during the Central Library's hours of operation. Deaf or hard of hearing customers may use Maryland Relay (#711 or 1-800-735-2258). Pratt Free Market is run at a different Pratt location (Southeast Anchor Library) and operates two days per week. | H18: Monday: 10 AM to 8 PM; Tuesday: 10 AM to 8 PM; Wednesday: 10 AM to 8 PM; Thursday: 10 AM to 8 PM; Friday: 10 AM to 5 PM; Saturday: 10 AM to 5 PM; Sunday: Closed | I18: Youth, Family, & General Support Services | J18: Enoch Pratt Free Library – Central is Baltimore’s main public library branch offering on-site book and media lending, reading and study spaces, public computers and internet access, research help and librarian appointments, meeting rooms, and a range of outreach and community-assistance programs and mobile services. | K18: https://www.prattlibrary.org/ | L18: Google reviewers commonly praise the Central Library’s renovated facility, large collection, quiet resourceful spaces, and helpful staff; recent reviews continue to reflect these positive themes. A minority of reviewers report service breakdowns such as missed or poorly followed-up appointments for assistance. Official sources (the library’s website and public records) corroborate that this branch is active and operating regular programs and services. | M18: 84.984086 | N18: 94.655732 | O18: accepted google identity: 14.2/15; review volume: 30.0/30; review consistency: 3.2/7; review freshness: 8.0/8; verified website: 14.2/15; confirmed irs record: 20.0/20; source corroboration: 5.0/5; Synthesis metadata: high (not part of numeric confidence) | P18: 8312026 | Q18: =IF(OR(ISBLANK(M18), ISBLANK(N18)), "", IF(N18 < Sheet3!$B$6, "Insufficient Reviews", IF(M18 >= Sheet3!$B$2, "Highly Reliable", IF(M18 >= Sheet3!$B$3, "Reliable", IF(M18 >= Sheet3!$B$4, "Mixed Reviews", "Low Reliability"))))) -> Highly Reliable
A19: =A18+1 -> 18 | B19: 101 W Mt Royal Ave, Baltimore, MD 21201 | C19: 39.305085 | D19: -76.61791 | E19: (410) 234-0023 | F19: Chana Helpline | H19: Monday: 9:00 am - 8:00 pm; Tuesday: 9:00 am - 8:00 pm; Wednesday: 9:00 am - 8:00 pm; Thursday: 9:00 am - 8:00 pm; Friday: 9:00 am - 4:00 pm; Saturday CLOSED; Sunday: 9:00 am - 12:00 pm | I19: Safety & Anti-Violence | J19: Provides support, advocacy, and educational services for people affected by intimate partner violence and domestic abuse, focusing on survivor support and related advocacy/education. | K19: http://chanabaltimore.org/ | L19: Available reviewer comments are strongly positive: reviewers describe the organization as knowledgeable, supportive, and active in advocacy and education around intimate partner violence/domestic abuse. There are no recurring complaints or negative themes in the provided review text, and the most recent review aligns with earlier praise. Public website content was not substantive, so reviewer feedback and the Google Maps category are the primary corroborating signals. | M19: 80.01054 | N19: 55.165885 | O19: accepted google identity: 14.2/15; review volume: 10.1/30; review consistency: 7.0/7; review freshness: 6.3/8; verified website: 14.2/15; confirmed irs record: 0.0/20; source corroboration: 3.3/5; Synthesis metadata: medium (not part of numeric confidence) | P19: 8312026 | Q19: =IF(OR(ISBLANK(M19), ISBLANK(N19)), "", IF(N19 < Sheet3!$B$6, "Insufficient Reviews", IF(M19 >= Sheet3!$B$2, "Highly Reliable", IF(M19 >= Sheet3!$B$3, "Reliable", IF(M19 >= Sheet3!$B$4, "Mixed Reviews", "Low Reliability"))))) -> Reliable
A20: =A19+1 -> 19 | B20: 8503 Lasalle Rd, Towson, MD 21286 | C20: 39.393727 | D20: -76.5769 | E20: (410) 377-8111 | F20: Turnaround Inc | G20: Services are for survivors of intimate partner violence, sexual violence, and human trafficking in Baltimore County and Baltimore City; human trafficking services extend to Howard County. A 24/7 crisis helpline and crisis text line are published. Some programs note appointments are required or recommended; certain programs (e.g., abuser-intervention) are fee-based while legal services are described as free consultations/representation. (Sources: evidence_id 6 — official website; evidence_id 4 — Google Maps listing.) | H20: Monday: 9 AM to 5 PM; Tuesday: 9 AM to 5 PM; Wednesday: 9 AM to 5 PM; Thursday: 9 AM to 5 PM; Friday: 9 AM to 5 PM; Saturday: Closed; Sunday: Closed | I20: Safety & Anti-Violence | J20: TurnAround, Inc. is a Baltimore-area violence survivor support organization that operates a crisis helpline/text line and provides trauma-informed services including therapy, advocacy and resource navigation, legal assistance, an abuser-intervention program, and community training and outreach. | K20: http://www.turnaroundinc.org/ | L20: Reviewer feedback shows a split pattern: some survivors report receiving immediate, tangible help (accommodations, transportation, food), while many recent reviewers describe problems with responsiveness, follow-through, and unprofessional communications when seeking help or shelter. Several reviews raise safety- and trust-related concerns tied to delayed or missing support, and the latest reviews continue to emphasize those negative experiences. Owner/agency responses to the public reviews are not present in the provided sample. | M20: 55.093588 | N20: 88.884948 | O20: accepted google identity: 14.2/15; review volume: 26.5/30; review consistency: 2.6/7; review freshness: 6.3/8; verified website: 14.2/15; confirmed irs record: 20.0/20; source corroboration: 5.0/5; Synthesis metadata: high (not part of numeric confidence) | P20: 8312026 | Q20: =IF(OR(ISBLANK(M20), ISBLANK(N20)), "", IF(N20 < Sheet3!$B$6, "Insufficient Reviews", IF(M20 >= Sheet3!$B$2, "Highly Reliable", IF(M20 >= Sheet3!$B$3, "Reliable", IF(M20 >= Sheet3!$B$4, "Mixed Reviews", "Low Reliability"))))) -> Low Reliability
A21: =A20+1 -> 20 | B21: 915 Sterrett St, Baltimore, MD 21230 | C21: 39.281118 | D21: -76.626992 | E21: (667) 600-3776 | F21: Catholic Charities Head Start of Baltimore City | I21: Youth, Family, & General Support Services | J21: A Head Start center operated by Catholic Charities located in Baltimore that provides early childhood / Head Start daycare and related program activities at the Head Start of Baltimore City site. The presence of this Head Start location is corroborated by the Google Maps listing and the organization’s official website. | K21: http://www.catholiccharities-md.org/ | L21: The Google Maps listing and the organization’s official website both corroborate the existence of a Head Start location at this address, and the website is reachable. Review text was not available for analysis, so user feedback and on-the-ground experience could not be assessed. The listing does not publish structured opening hours, limiting scheduling details. | M21: 72 | N21: 40.724992 | O21: accepted google identity: 14.2/15; review volume: 8.9/30; review consistency: 0.0/7; review freshness: 0.0/8; verified website: 14.2/15; confirmed irs record: 0.0/20; source corroboration: 3.3/5; Synthesis metadata: medium (not part of numeric confidence) | P21: 8312026 | Q21: =IF(OR(ISBLANK(M21), ISBLANK(N21)), "", IF(N21 < Sheet3!$B$6, "Insufficient Reviews", IF(M21 >= Sheet3!$B$2, "Highly Reliable", IF(M21 >= Sheet3!$B$3, "Reliable", IF(M21 >= Sheet3!$B$4, "Mixed Reviews", "Low Reliability"))))) -> Reliable
A22: =A21+1 -> 21 | B22: A. Hoen and Co., 2101 E Biddle St Ste 1100, Baltimore, MD 21213 | C22: 39.304115 | D22: -76.587923 | E22: (410) 261-3500 | F22: Strong City Baltimore | H22: Monday: 9 AM to 5 PM; Tuesday: 9 AM to 5 PM; Wednesday: 9 AM to 5 PM; Thursday: 9 AM to 5 PM; Friday: 9 AM to 5 PM; Saturday: Closed; Sunday: Closed | I22: Employment, Training, & Education | J22: A physical education center listed in Baltimore that appears to offer in-person learning programs at this address. | L22: Google Maps listing and hours are available for a physical location, but independent corroboration is limited. Public review text is sparse and mixed: the sampled reviews include a recent positive, text-free rating and an earlier review that specifically complained the telephone number did not work. Because reviews and other corroborating sources are limited and the organization’s website could not be verified, program details and access procedures are not well-documented from the available evidence. | M22: 62.717292 | N22: 35.060608 | O22: accepted google identity: 14.2/15; review volume: 15.1/30; review consistency: 0.0/7; review freshness: 4.0/8; verified website: 0.0/15; confirmed irs record: 0.0/20; source corroboration: 1.7/5; Synthesis metadata: medium (not part of numeric confidence) | P22: 8312026 | Q22: =IF(OR(ISBLANK(M22), ISBLANK(N22)), "", IF(N22 < Sheet3!$B$6, "Insufficient Reviews", IF(M22 >= Sheet3!$B$2, "Highly Reliable", IF(M22 >= Sheet3!$B$3, "Reliable", IF(M22 >= Sheet3!$B$4, "Mixed Reviews", "Low Reliability"))))) -> Insufficient Reviews
A23: =A22+1 -> 22 | B23: 620 Fallsway, Baltimore, MD 21202 | C23: 39.297412 | D23: -76.610586 | E23: (667) 600-3230 | F23: Weinberg Housing and Resource Center | G23: Open to adult men and women experiencing homelessness. All prospective residents must contact the Mayor's Office of Homeless Services Coordinated Entry Line at 443-984-9540 to request shelter referrals between 9:30am and 9:00pm (Coordinated Entry intake required). | H23: Monday: 9 AM to 5 PM; Tuesday: 9 AM to 5 PM; Wednesday: 9 AM to 5 PM; Thursday: Closed; Friday: 9 AM to 5 PM; Saturday: Closed; Sunday: 9 AM to 5 PM | I23: Housing & Shelter | J23: A low-barrier emergency shelter and homeless-services site that provides short-term emergency shelter for adults and connects residents to case management and housing-placement supports. The program also offers on-site basic supports such as meals, laundry, client transportation, workforce development training, and referrals to behavioral-health services. | K23: http://www.cc-md.org/WHRC | L23: Public reviewer feedback contains both strong praise for the center’s resources and staff support and recurring complaints about safety and cleanliness. Positive comments emphasize plentiful resources and staff who help residents seeking stability; recurring negatives raise bed‑bug reports, theft/safety concerns, and instances of unsympathetic or unhelpful intake interactions. The most recent reviews tilt toward those negative issues, and there are no visible owner responses in the public review thread. | M23: 70.419503 | N23: 71.606093 | O23: accepted google identity: 14.2/15; review volume: 30.0/30; review consistency: 1.8/7; review freshness: 8.0/8; verified website: 14.2/15; confirmed irs record: 0.0/20; source corroboration: 3.3/5; Synthesis metadata: high (not part of numeric confidence) | P23: 8312026 | Q23: =IF(OR(ISBLANK(M23), ISBLANK(N23)), "", IF(N23 < Sheet3!$B$6, "Insufficient Reviews", IF(M23 >= Sheet3!$B$2, "Highly Reliable", IF(M23 >= Sheet3!$B$3, "Reliable", IF(M23 >= Sheet3!$B$4, "Mixed Reviews", "Low Reliability"))))) -> Reliable
A24: =A23+1 -> 23 | B24: 2401 Liberty Heights Ave #302, Baltimore, MD 21215 | C24: 39.316766 | D24: -76.654108 | E24: (410) 396-7873 | F24: Northwest Career Center (Background Friendly Job Center) | G24: Stated eligibility: services for adult Baltimore City residents. No appointment required (drop‑in). The official site provides a form to request/receive services (online intake option). | H24: Monday: 8:30 AM to 4:30 PM; Tuesday: 8:30 AM to 4:30 PM; Wednesday: 8:30 AM to 4:30 PM; Thursday: 8:30 AM to 4:30 PM; Friday: 8:30 AM to 4:30 PM; Saturday: Closed; Sunday: Closed | I24: Employment, Training, & Education | J24: A city-run career center that provides access to background‑friendly jobs, workforce training, and job‑search supports (including resume and placement help). The listing and site indicate services are offered as a physical, drop‑in location. | K24: https://moed.baltimorecity.gov/northwest-baltimore-career-center-contact | L24: User reviews describe staff who can be helpful and willing to assist, especially with resume and job search needs, but also repeatedly note long waits, limited daily capacity, and some negative experiences around phone information or perceived bias in access. Several recent reviews are negative, indicating that service experiences remain mixed; the listing owner has responded to some feedback. | M24: 67.855821 | N24: 70.598528 | O24: accepted google identity: 14.2/15; review volume: 30.0/30; review consistency: 1.0/7; review freshness: 7.8/8; verified website: 14.2/15; confirmed irs record: 0.0/20; source corroboration: 3.3/5; Synthesis metadata: medium (not part of numeric confidence) | P24: 8312026 | Q24: =IF(OR(ISBLANK(M24), ISBLANK(N24)), "", IF(N24 < Sheet3!$B$6, "Insufficient Reviews", IF(M24 >= Sheet3!$B$2, "Highly Reliable", IF(M24 >= Sheet3!$B$3, "Reliable", IF(M24 >= Sheet3!$B$4, "Mixed Reviews", "Low Reliability"))))) -> Mixed Reviews
A25: =A24+1 -> 24 | B25: 1410 Bush St, Baltimore, MD 21230 | C25: 39.27629 | D25: -76.635498 | E25: (410) 396-1052 | F25: Employment Connection Center | G25: Website hosts a form to request services (online intake). A Google Maps review reports the center referring people to a different site based on zip code; this user report suggests there may be geographic-eligibility or service-area rules reported by staff, but that restriction is documented only in a reviewer comment. | H25: Monday: 8:30 AM to 4:30 PM; Tuesday: 8:30 AM to 4:30 PM; Wednesday: 8:30 AM to 4:30 PM; Thursday: 8:30 AM to 4:30 PM; Friday: 8:30 AM to 4:30 PM; Saturday: Closed; Sunday: Closed | I25: Employment, Training, & Education | J25: A physical Employment Connection Center operated through Baltimore City that provides in-person employment and training-related services for people seeking work, with an online intake form to request services. | K25: https://moed.baltimorecity.gov/south-baltimore-employment-connections-center | L25: Google Maps reviewers most commonly describe helpful staff, counselors, and the center being a useful resource for finding jobs or training. Recurring negative reports say staff have sometimes refused entry or sent people to other locations and that posted hours were not always honored; the newest reviews echo those access and hours complaints. The listing owner has responded to multiple reviewer complaints, indicating some owner responsiveness to feedback. | M25: 71.683008 | N25: 60.928063 | O25: accepted google identity: 13.3/15; review volume: 24.2/30; review consistency: 0.9/7; review freshness: 5.8/8; verified website: 13.3/15; confirmed irs record: 0.0/20; source corroboration: 3.3/5; Synthesis metadata: high (not part of numeric confidence) | P25: 8312026 | Q25: =IF(OR(ISBLANK(M25), ISBLANK(N25)), "", IF(N25 < Sheet3!$B$6, "Insufficient Reviews", IF(M25 >= Sheet3!$B$2, "Highly Reliable", IF(M25 >= Sheet3!$B$3, "Reliable", IF(M25 >= Sheet3!$B$4, "Mixed Reviews", "Low Reliability"))))) -> Reliable
A26: =A25+1 -> 25 | B26: 3001 E Madison St, Baltimore, MD 21205 | C26: 39.299925 | D26: -76.575042 | E26: (410) 396-9030 | F26: Eastside Career Center | G26: Site materials state services are offered to adult Baltimore City residents; no appointment is required and walk-ins are welcome. The official site affirms equal-opportunity nondiscrimination and invites customers to request auxiliary aids or interpreter services as needed. | H26: Monday: 8:30 AM to 4:30 PM; Tuesday: 8:30 AM to 4:30 PM; Wednesday: 8:30 AM to 4:30 PM; Thursday: 8:30 AM to 4:30 PM; Friday: 8:30 AM to 4:30 PM; Saturday: Closed; Sunday: Closed | I26: Employment, Training, & Education | J26: A Baltimore City American Job Center location that provides in-person help with job search and workforce services including career counseling, connections to training programs, résumé help, workshops, and access to computers and basic office equipment. Employer-facing business services are also listed on the official site. | K26: https://www.labor.maryland.gov/county/bacity/ | L26: Reviewers commonly report approachable and helpful staff and that the center provides useful resources for finding work and training. Recurring concerns in reviews include long waits, inconsistent front-desk experiences, occasional early closing, and frustration that some in-person assistance directs users back to web resources. Recent reviews include positive comments about staff and job help alongside some ongoing complaints, and center staff have posted responses to several critical reviews. | M26: 74.801744 | N26: 70.06193 | O26: accepted google identity: 14.2/15; review volume: 30.0/30; review consistency: 1.1/7; review freshness: 7.2/8; verified website: 14.2/15; confirmed irs record: 0.0/20; source corroboration: 3.3/5; Synthesis metadata: high (not part of numeric confidence) | P26: 8312026 | Q26: =IF(OR(ISBLANK(M26), ISBLANK(N26)), "", IF(N26 < Sheet3!$B$6, "Insufficient Reviews", IF(M26 >= Sheet3!$B$2, "Highly Reliable", IF(M26 >= Sheet3!$B$3, "Reliable", IF(M26 >= Sheet3!$B$4, "Mixed Reviews", "Low Reliability"))))) -> Reliable
A27: =A26+1 -> 26 | B27: 2305 N Charles St, Baltimore, MD 21218 | C27: 39.314737 | D27: -76.616788 | E27: (410) 230-0630 | F27: Maryland New Directions Inc | G27: Programs are offered at no cost. Enrollment requires completion of the Career Focus (job-readiness) step prior to industry-specific program enrollment. Services are targeted to Baltimore-area residents age 18 and older; the organization states it does not discriminate in program administration. | H27: Monday: 8:30 AM to 4:30 PM; Tuesday: 8:30 AM to 4:30 PM; Wednesday: 8:30 AM to 4:30 PM; Thursday: 8:30 AM to 4:30 PM; Friday: 8:30 AM to 4:30 PM; Saturday: Closed; Sunday: Closed | I27: Employment, Training, & Education | J27: Maryland New Directions provides no-cost employment coaching and career-training programs for adults, including a required job-readiness course followed by industry-specific training that leads to industry-recognized credentials (examples cited include forklift and OSHA training and commercial driver permit preparation). The organization also supports resume-building, soft-skill development, and employer connections to help participants find work. | K27: http://www.mdnewdirections.org/ | L27: Public Google Maps reviewers consistently praise staff as helpful and supportive, and they report positive experiences with the training, coaching, and credential preparation (reviews frequently mention resume help, forklift certification, and job-readiness). Owner responses are present on reviews, and recent review text remains strongly positive, indicating ongoing consistent performance. The listing and an accepted official website snapshot both corroborate program details, and registry/filing signals further support the organization’s active identity. | M27: 86.843867 | N27: 95.549511 | O27: accepted google identity: 14.2/15; review volume: 30.0/30; review consistency: 4.2/7; review freshness: 7.8/8; verified website: 14.2/15; confirmed irs record: 20.0/20; source corroboration: 5.0/5; Synthesis metadata: high (not part of numeric confidence) | P27: 8312026 | Q27: =IF(OR(ISBLANK(M27), ISBLANK(N27)), "", IF(N27 < Sheet3!$B$6, "Insufficient Reviews", IF(M27 >= Sheet3!$B$2, "Highly Reliable", IF(M27 >= Sheet3!$B$3, "Reliable", IF(M27 >= Sheet3!$B$4, "Mixed Reviews", "Low Reliability"))))) -> Highly Reliable
A28: =A27+1 -> 27 | B28: 201 N Charles St, Baltimore, MD 21201 | C28: 39.291343 | D28: -76.614754 | E28: (410) 234-8040 | F28: Job Opportunities Task Force | G28: BetterU Construction Training is for Baltimore residents and requires a high school diploma or GED. The facility listing indicates a wheelchair-accessible entrance and wheelchair-accessible parking. | H28: Monday: 9 AM to 5 PM; Tuesday: 9 AM to 5 PM; Wednesday: 9 AM to 5 PM; Thursday: 9 AM to 5 PM; Friday: 9 AM to 5 PM; Saturday: Closed; Sunday: Closed | I28: Employment, Training, & Education | J28: Provides workforce-development and training programs aimed at reducing educational and employment barriers for low-wage workers. The organization operates BetterU Construction Training, a 14-week pre-apprenticeship that covers entry-level plumbing, carpentry, and electrical skills. | K28: http://www.jotf.org/ | L28: Public review text is very sparse and provides little or no written feedback, so reviewer themes are not discernible. The Google Maps listing includes a program description, phone number, structured hours, and accessibility details, but the organization’s website currently returns an error page. Because independent corroboration is limited and on-site web content is unavailable, the available information should be treated as only moderately verified. | M28: 73.366238 | N28: 50.677918 | O28: accepted google identity: 14.2/15; review volume: 8.9/30; review consistency: 7.0/7; review freshness: 3.0/8; verified website: 14.2/15; confirmed irs record: 0.0/20; source corroboration: 3.3/5; Synthesis metadata: medium (not part of numeric confidence) | P28: 8312026 | Q28: =IF(OR(ISBLANK(M28), ISBLANK(N28)), "", IF(N28 < Sheet3!$B$6, "Insufficient Reviews", IF(M28 >= Sheet3!$B$2, "Highly Reliable", IF(M28 >= Sheet3!$B$3, "Reliable", IF(M28 >= Sheet3!$B$4, "Mixed Reviews", "Low Reliability"))))) -> Reliable
A29: =A28+1 -> 28 | B29: 898 Airport Park Rd, Glen Burnie, MD 21061 | C29: 39.173685 | D29: -76.64452 | E29: (410) 242-9674 | F29: Vehicles for Change Corporate Office | G29: Keys to Independence program is described as providing affordable vehicles to low-income families. Full Circle Training enrolls justice-impacted individuals and others facing employment barriers. Vehicle awards and training appear to require an application and may involve a waiting period or eligibility review. (All access requirements are stated on the organization website and Google listing.) | H29: Monday: 8 AM to 5 PM; Tuesday: 8 AM to 5 PM; Wednesday: 8 AM to 5 PM; Thursday: 8 AM to 5 PM; Friday: 8 AM to 5 PM; Saturday: Closed; Sunday: Closed | I29: Youth, Family, & General Support Services | J29: Vehicles for Change operates vehicle-donation and resale programs that fund vehicle awards to low-income families, runs hands-on automotive workforce training (Full Circle Auto Training and VR training), and operates community auto-repair centers that support its mission. | K29: http://vehiclesforchange.org/ | L29: Reviewers commonly praise staff helpfulness, a smooth donation process, and positive experiences with the organization’s repair and training programs. Recurring concerns in the reviews center on slow or unclear communication about vehicle-award applications and waiting times. Owner responses to reviews are frequent, and recent reviews in the sample trend toward positive feedback; the organization’s IRS and website records corroborate its identity and programs. | M29: 76.062767 | N29: 90.856813 | O29: accepted google identity: 14.2/15; review volume: 30.0/30; review consistency: 0.7/7; review freshness: 6.7/8; verified website: 14.2/15; confirmed irs record: 20.0/20; source corroboration: 5.0/5; Synthesis metadata: high (not part of numeric confidence) | P29: 8312026 | Q29: =IF(OR(ISBLANK(M29), ISBLANK(N29)), "", IF(N29 < Sheet3!$B$6, "Insufficient Reviews", IF(M29 >= Sheet3!$B$2, "Highly Reliable", IF(M29 >= Sheet3!$B$3, "Reliable", IF(M29 >= Sheet3!$B$4, "Mixed Reviews", "Low Reliability"))))) -> Reliable
A30: =A29+1 -> 29 | B30: 800 W 36th St, Baltimore, MD 21211 | C30: 39.331505 | D30: -76.629766 | E30: (443) 402-5828 | F30: St. Luke's Church on the Avenue | G30: The Avenue Drop-In is conducted by a harm-reduction partner and runs currently on Fridays from 10:00am–11:00am; participants may receive services such as syringe exchange, hygiene supplies, treatment referrals, Narcan training/distribution, and a takeaway hot lunch. Participants of the drop-in are eligible for $25 vouchers to the Lost & Found Thrift Shop. The thrift shop accepts donations during its operating hours. (All access details supported by website: evidence_id 44; additional site accessibility / amenities noted on Google Maps: evidence_id 42.) | H30: Avenue Drop-In: Every Friday, 10:00am–11:00am. Gathering of Holy Communion (in person): Sunday mornings, 10:00am. Benedictine Morning Prayer: Monday–Friday, 7:30am. (All times taken from the organization website: evidence_id 44.) | I30: Food & Essential Needs | J30: St. Luke’s Church on the Avenue operates a neighborhood church and community site that hosts a thrift shop, a weekly drop-in run with a harm-reduction partner (including syringe exchange, hygiene supplies, naloxone training/distribution, referrals), a community garden, and periodic food distribution/hot lunch take-away. | K30: https://www.churchontheavenuehampden.org/ | L30: Recent Google Maps reviews consistently describe the location as a positive community space and explicitly praise its food distribution and related community programs. Reviewers' comments emphasize effective food distribution and an active neighborhood role; there are no recurring complaints evident in the recent sample. The most recent reviews continue the same positive themes, suggesting consistent experiences over time. | M30: 80.57803 | N30: 67.685292 | O30: accepted google identity: 14.2/15; review volume: 22.3/30; review consistency: 5.6/7; review freshness: 8.0/8; verified website: 14.2/15; confirmed irs record: 0.0/20; source corroboration: 3.3/5; Synthesis metadata: high (not part of numeric confidence) | P30: 8312026 | Q30: =IF(OR(ISBLANK(M30), ISBLANK(N30)), "", IF(N30 < Sheet3!$B$6, "Insufficient Reviews", IF(M30 >= Sheet3!$B$2, "Highly Reliable", IF(M30 >= Sheet3!$B$3, "Reliable", IF(M30 >= Sheet3!$B$4, "Mixed Reviews", "Low Reliability"))))) -> Reliable
A31: =A30+1 -> 30 | B31: 2631 Huntingdon Ave, Baltimore, MD 21211 | C31: 39.31976 | D31: -76.621675 | E31: (410) 929-3688 | F31: Church of the Guardian Angel | G31: Reviewers state the Wednesday food pantry is available “to anyone in need.” Review text also describes school supplies and holiday gifts provided to neighborhood children. Some reviewers recalled past limits on non-neighborhood attendees but later reviews indicate the church accepts visitors from outside the immediate neighborhood. | H31: Monday: Closed; Tuesday: Closed; Wednesday: 9 to 10 AM; Thursday: Closed; Friday: Closed; Saturday: Closed; Sunday: 10 to 11 AM | I31: Food & Essential Needs | J31: A neighborhood Episcopal church that holds regular Sunday worship (including a Spanish-language mass) and operates community support activities; reviewers report a weekly Wednesday morning food pantry and distributions of school supplies and holiday gifts for neighborhood children. | K31: https://www.facebook.com/Church-of-the-Guardian-Angel-259556444135884/ | L31: Google Maps reviewers consistently describe the congregation as warm, friendly, and welcoming and report active community supports such as a Wednesday food pantry and distributions of school supplies and holiday gifts. A few reviewers recalled an earlier period with restrictive attendance practices, but more recent reviews emphasize renewed openness and positive interactions with current staff. Review feedback is uniformly positive and the newest reviews continue that pattern. | M31: 85.407938 | N31: 85.309197 | O31: accepted google identity: 13.5/15; review volume: 21.4/30; review consistency: 7.0/7; review freshness: 4.9/8; verified website: 13.5/15; confirmed irs record: 20.0/20; source corroboration: 5.0/5; Synthesis metadata: high (not part of numeric confidence) | P31: 8312026 | Q31: =IF(OR(ISBLANK(M31), ISBLANK(N31)), "", IF(N31 < Sheet3!$B$6, "Insufficient Reviews", IF(M31 >= Sheet3!$B$2, "Highly Reliable", IF(M31 >= Sheet3!$B$3, "Reliable", IF(M31 >= Sheet3!$B$4, "Mixed Reviews", "Low Reliability"))))) -> Highly Reliable
A32: =A31+1 -> 31 | B32: 5353 Park Heights Ave, Baltimore, MD 21215 | C32: 39.350375 | D32: -76.680453 | E32: (410) 664-0907 | F32: Dayspring Inc. | G32: Open to community; program-specific | H32: Sun worship; weekly activities | I32: Youth, Family, & General Support Services | J32: Operates locally based programs, events, and resources focused on children and families, and offers volunteer opportunities and program registration for community participants. | K32: http://dayspringinc.org/ | L32: Public review feedback is unavailable: the Google Maps listing has no public reviews and no fetched review text to indicate user experiences. The organization has a verified website and a corroborating Google Maps listing, and archived snapshots show the site has been active in recent years, which together support the organization’s online presence and program descriptions. An IRS Business Master File match indicates a recent 2024 filing, further supporting ongoing organizational activity. Because there are no public reviews, judgments about service quality, consistency, or client experience cannot be drawn from review text. | M32: 10.5 | N32: 31.833333 | O32: accepted google identity: 14.2/15; review volume: 0.0/30; review consistency: 0.0/7; review freshness: 0.0/8; verified website: 14.2/15; confirmed irs record: 0.0/20; source corroboration: 3.3/5; Synthesis metadata: medium (not part of numeric confidence) | P32: 8312026 | Q32: =IF(OR(ISBLANK(M32), ISBLANK(N32)), "", IF(N32 < Sheet3!$B$6, "Insufficient Reviews", IF(M32 >= Sheet3!$B$2, "Highly Reliable", IF(M32 >= Sheet3!$B$3, "Reliable", IF(M32 >= Sheet3!$B$4, "Mixed Reviews", "Low Reliability"))))) -> Insufficient Reviews
